<?xml version="1.0"?>
<robot name="blinky">
  <link name="base_link">
    <visual>
      <geometry>
        <box size=".395 .18 .1"/>
      </geometry>
      <material name="red">
        <color rgba="0 0 .8 .3"/>
      </material>
    </visual>
  </link>

  <link name="rear_right_wheel">
    <visual>
      <geometry>
        <cylinder length=".045" radius=".05"/>
      </geometry>
      <material name="black">
        <color rgba="0 0 0 .7"/>
      </material>
      <origin xyz="0 -.02 0" rpy="1.57075 0 0"/>
    </visual>
  </link>

  <joint name="rear_right_wheel_joint" type="continuous">
    <axis xyz="0 1 0"/>
    <parent link="base_link"/>
    <child link="rear_right_wheel"/>
    <origin xyz="-.14 -.10 -.05"/>
  </joint>

  <link name="rear_left_wheel">
    <visual>
      <geometry>
        <cylinder length=".045" radius=".05"/>
      </geometry>
      <material name="black"/>
      <origin xyz="0 .02 0" rpy="1.57075 0 0"/>
    </visual>
  </link>

  <joint name="rear_left_wheel_joint" type="continuous">
    <axis xyz="0 1 0"/>
    <parent link="base_link"/>
    <child link="rear_left_wheel"/>
    <origin xyz="-.14 0.1 -.05"/>
  </joint>

  <link name="front_right_steering"/>

  <joint name="front_right_steering_joint" type="continuous">
    <axis xyz="0 0 1"/>
    <parent link="base_link"/>
    <child link="front_right_steering"/>
    <origin xyz=".14 -0.1 -.05"/>
  </joint>

  <link name="front_right_wheel">
    <visual>
      <geometry>
        <cylinder length=".045" radius=".05"/>
      </geometry>
      <material name="black"/>
      <origin xyz="0 -.02 0" rpy="1.57075 0 0"/>
    </visual>
  </link>

  <joint name="front_right_wheel_joint" type="continuous">
    <axis xyz="0 1 0"/>
    <parent link="front_right_steering"/>
    <child link="front_right_wheel"/>
  </joint>

  <link name="front_left_steering"/>
 
  <joint name="front_left_steering_joint" type="continuous">
    <axis xyz="0 0 1"/>
    <parent link="base_link"/>
    <child link="front_left_steering"/>
    <origin xyz=".14 .1 -.05"/>
  </joint>

  <link name="front_left_wheel">
    <visual>
      <geometry>
        <cylinder length=".045" radius=".05"/>
      </geometry>
      <material name="black"/>
      <origin xyz="0 .02 0" rpy="1.57075 0 0"/>
    </visual>
  </link>


  <joint name="front_left_wheel_joint" type="continuous">
    <axis xyz="0 1 0"/>
    <parent link="front_left_steering"/>
    <child link="front_left_wheel"/>
  </joint>
</robot>

